#VRML_SIM R2022a utf8
WorldInfo {
}
Viewpoint {
  orientation -0.029705670269594087 0.9771945319908433 0.2102579839174511 0.287263691324045
  position -4.37081335058609 -0.7711218971595231 2.620161280486711
}
TexturedBackground {
}
TexturedBackgroundLight {
}
RectangleArena {
  name "Ground"
  floorSize 5 5
}
Robot {
  children [
    Shape {
      appearance DEF base_link_material PBRAppearance {
        baseColor 0.45098 0.823529 0.0862745
        roughness 1
        metalness 0
      }
      geometry DEF base_link Mesh {
        url [
          "/home/wei/CLionProjects/NewTravel/Data/Test/aa.STL"
        ]
      }
    }
    HingeJoint {
      jointParameters HingeJointParameters {
        axis 0 0 1
      }
      device [
        RotationalMotor {
          name "joint_1"
          maxTorque 10000
        }
        PositionSensor {
          name "joint_1_sensor"
        }
      ]
      endPoint Solid {
        translation 0 0 0.375
        rotation 1 0 0 -1.5708
        children [
          Shape {
            appearance DEF Link_1_material PBRAppearance {
              baseColor 0.447059 0.623529 0.811765
              roughness 1
              metalness 0
            }
            geometry DEF Link_1 Mesh {
              url [
                "/home/wei/CLionProjects/NewTravel/Data/Test/bb.STL"
              ]
            }
          }
          HingeJoint {
            jointParameters HingeJointParameters {
              axis 0 0 1
            }
            device [
              RotationalMotor {
                name "joint_2"
                maxTorque 10000
              }
              PositionSensor {
                name "joint_2_sensor"
              }
            ]
            endPoint Solid {
              children [
                Shape {
                  appearance DEF Link_2_material PBRAppearance {
                    baseColor 0.678431 0.498039 0.658824
                    roughness 1
                    metalness 0
                  }
                  geometry DEF Link_2 Mesh {
                    url [
                      "/home/wei/CLionProjects/NewTravel/Data/Test/cc.STL"
                    ]
                  }
                }
                HingeJoint {
                  jointParameters HingeJointParameters {
                    axis 0 0 1
                    anchor 0 -0.4 0.02
                  }
                  device [
                    RotationalMotor {
                      name "Joint_3"
                      maxTorque 10000
                    }
                    PositionSensor {
                      name "Joint_3_sensor"
                    }
                  ]
                  endPoint Solid {
                    translation 0 -0.4 0.02
                    children [
                      Shape {
                        appearance DEF Link_3_material PBRAppearance {
                          baseColor 0.913725 0.72549 0.431373
                          roughness 1
                          metalness 0
                        }
                        geometry DEF Link_3 Mesh {
                          url [
                            "/home/wei/CLionProjects/NewTravel/Data/Test/dd.STL"
                          ]
                        }
                      }
                      HingeJoint {
                        jointParameters HingeJointParameters {
                          axis 0 -1 -4e-06
                        }
                        device [
                          RotationalMotor {
                            name "Joint_4"
                            maxTorque 10000
                          }
                          PositionSensor {
                            name "Joint_4_sensor"
                          }
                        ]
                        endPoint Solid {
                          rotation 1 0 0 1.5708
                          children [
                            Shape {
                              appearance DEF Link_4_material PBRAppearance {
                                baseColor 0.960784 0.47451 0
                                roughness 1
                                metalness 0
                              }
                              geometry DEF Link_4 Mesh {
                                url [
                                  "/home/wei/CLionProjects/NewTravel/Data/Test/ee.STL"
                                ]
                              }
                            }
                            HingeJoint {
                              jointParameters HingeJointParameters {
                                axis 0 1 -4e-06
                                anchor 0 0 0.45
                              }
                              device [
                                RotationalMotor {
                                  name "Joint_5"
                                  maxTorque 10000
                                }
                                PositionSensor {
                                  name "Joint_5_sensor"
                                }
                              ]
                              endPoint Solid {
                                translation 0 0 0.45
                                rotation -1 0 0 1.5708
                                children [
                                  Shape {
                                    appearance DEF Link_5_material PBRAppearance {
                                      baseColor 0.45098 0.823529 0.0862745
                                      roughness 1
                                      metalness 0
                                    }
                                    geometry DEF Link_5 Mesh {
                                      url [
                                        "/home/wei/CLionProjects/NewTravel/Data/Test/ff.STL"
                                      ]
                                    }
                                  }
                                  HingeJoint {
                                    jointParameters HingeJointParameters {
                                      axis 0 -1 -4e-06
                                      anchor 0 -0.07 0
                                    }
                                    device [
                                      RotationalMotor {
                                        name "Joint_6"
                                        maxTorque 10000
                                      }
                                      PositionSensor {
                                        name "Joint_6_sensor"
                                      }
                                    ]
                                    endPoint Solid {
                                      translation 0 -0.07 0
                                      rotation 1 0 0 1.5708
                                      children [
                                        Shape {
                                          appearance DEF Link_6_material PBRAppearance {
                                            baseColor 0.937255 0.160784 0.160784
                                            roughness 1
                                            metalness 0
                                          }
                                          geometry DEF Link_6 Mesh {
                                            url [
                                              "/home/wei/CLionProjects/NewTravel/Data/Test/gg.STL"
                                            ]
                                          }
                                        }
                                      ]
                                      name "Link_6"
                                      boundingObject USE Link_6
                                      physics Physics {
                                        centerOfMass [
                                          0 0 0
                                        ]
                                      }
                                    }
                                  }
                                ]
                                name "Link_5"
                                boundingObject USE Link_5
                                physics Physics {
                                  centerOfMass [
                                    0 0 0
                                  ]
                                }
                              }
                            }
                          ]
                          name "Link_4"
                          boundingObject USE Link_4
                          physics Physics {
                            centerOfMass [
                              0 0 0
                            ]
                          }
                        }
                      }
                    ]
                    name "Link_3"
                    boundingObject USE Link_3
                    physics Physics {
                      centerOfMass [
                        0 0 0
                      ]
                    }
                  }
                }
              ]
              name "Link_2"
              boundingObject USE Link_2
              physics Physics {
                centerOfMass [
                  0 0 0
                ]
              }
            }
          }
        ]
        name "Link_1"
        boundingObject USE Link_1
        physics Physics {
          centerOfMass [
            0 0 0
          ]
        }
      }
    }
  ]
  name "TX2-60L"
  boundingObject USE base_link
  controller "my_robot_controller"
}
